Workbook

Sheet overview
A1: overview
C2: aa | D2: nf | E2: nm | F2: mf | G2: mm | H2: na | I2: ma | J2: af | K2: am
B3: {=C11&" / "&C12} | C3: All | D3: Native Female | E3: Native Male | F3: Migrant Female | G3: Migrant Male | H3: Utility Native Male + Female | I3: Utility Migrant Male + Female | J3: Utility All Female | K3: Utility All Male | L3: Utility Other
B4: Information | C4: This column contains general values (like definitions and sources) | D4: This column is important for the correct calculation | E4: This column is important for the correct calculation | F4: This column is important for the correct calculation | G4: This column is important for the correct calculation | H4: This column only contains utilty values used to calculate the data on the left | I4: This column only contains utilty values used to calculate the data on the left | J4: This column only contains utilty values used to calculate the data on the left | K4: This column only contains utilty values used to calculate the data on the left | L4: This column only contains utilty values used to calculate the data on the left
B5: Editing this spreadsheet | C5: On a blue background, you can edit values and formulas
C6: On a green background, only change the formula (normally the formula should be right though)
C7: On a yellow background, don't change anything!
C8: On a dark grey background, you find important instructions
B10: Country
A11: na | B11: Acronym (e.g. "DE") | C11: IT
A12: nn | B12: Name | C12: Italy
A13: nd | B13: Date when the sheets were generated | C13: 2026-05-25 17:03
B15: Estimation | C15: This is an estimation of the tipping point
B17: Current population | C17: {=H17+I17} | D17: {=C34} | E17: pn, pm | H17: {=population!H109} | I17: {=population!I109}
B18: Gap native - migrant | C18: {=H17-I17} | D18: {=C18/C17}
B19: Birth / year according to population | H19: {=population!H9} | I19: {=population!I9}
B20: Birth / year according to fertility | H20: {=births!H11} | I20: {=births!I11}
B21: Birth / year used for estimation | D21: We prefer the number of births according to the fertility | H21: {=IF(ISNUMBER(H20),H20,H19)} | I21: {=IF(ISNUMBER(I20),I20,I19)}
B22: Deaths / year | H22: {=-deaths!H107} | I22: {=-deaths!I107}
B23: Migration balance / year | H23: {=migration!H9} | I23: {=migration!I9}
B24: Population delta / year | C24: {=I24-H24} | D24: {=C24/C17} | E24: dn, dm | H24: {=H21+H22+H23} | I24: {=I21+I22+I23}
B26: Years until 33% share of migrants | C26: {=(H$17-2*I$17)/(2*I$24-H$24)} | D26: y = (pn - 2*pm) / (2*dm - dn)
B27: Estimated tipping point for 33% share of migrants | C27: {=C$33+C26}
B28: Years until 50% share of migrants | C28: {=(H$17-I$17)/(I$24-H$24)} | D28: y = (pn - pm) / (dm - dn)
B29: Estimated tipping point for 50% share of migrants | C29: {=C$33+C28}
B31: Indicators | C31: This indicators are used to find differences between countries and thus show where the data collection might be wrong
B33: Year of the population numbers | C33: {=population!C7}
B34: Share of migrant population | C34: {=population!I109/population!C109} | D34: > 20% normally
B35: Births per 1 mio. women (15-49) | C35: {=I35/H35-1} | D35: > 30% normally | H35: {=births!H11/births!D9*1000000} | I35: {=births!I11/births!F9*1000000}
B36: Births per 1 mio. population | C36: {=I36/H36-1} | D36: > 50% normally due to younger migrant population | H36: {=births!H11/population!H109*1000000} | I36: {=births!I11/population!I109*1000000}
B37: Deaths per 1 mio. population | C37: {=I37/H37-1} | D37: < 0% normally due to younger migrant population | H37: {=deaths!H$107/population!H$109*1000000} | I37: {=deaths!I$107/population!I$109*1000000}
B38: Migration balance per 1 mio. of group | H38: {=migration!H111/population!H109*1000000} | I38: {=migration!I111/population!I109*1000000}
B39: Migration balance in % of population | H39: {=migration!H111/population!C109} | I39: {=migration!I111/population!D109}
B47: Migration Background | C47: How is the "Migration Background" defined in this country?
A49: i | B49: Definition of the 'migration background' | C49: There is no primary definition of migration background. One is either Italian with Italian citizenship or a foreigner without Italian citizenship.
A51: is | B51: Source of the data (verbal) | C51: https://www.istat.it/it/files/2020/04/Identit%C3%A0-e-percorsi.pdf; downloaded 46116
B52: URLs, where the data was found | C52: https://www.statistik.at/statistiken/bevoelkerung-und-soziales/bevoelkerung/migration-und-einbuergerung/migrationshintergrund, https://www.statistik.at/fileadmin/pages/435/Tabellensammlung_Migrationshintergrund_2025.ods, https://www.statistik.at/fileadmin/publications/Migration-Integration_2025.pdf
B53: Date, when the data was downloaded | C53: 2026-05-20
B54: Manual remarks (not for AI!)
B55: Remarks of the AI (e.g. calculation) | C55: MH-Anteil gesamt 2025 (Mikrozensus-Jahresdurchschnitt): 28,2 % (2.553,6 von 9.043,7 Tsd. in Privathaushalten). Davon 1. Generation 1.901,2 Tsd., 2. Generation 652,4 Tsd. Für die Pop-Aufschlüsselung wurde der MH-Anteil pro 5-Jahres-Altersgruppe × Geschlecht auf die POPREG-Einzelaltersstruktur (Stichtag 01.01.2025) angewandt. Siehe population!B115 für Methodik-Details.
...

Sheet population
A1: population
C2: aa | D2: nf | E2: nm | F2: mf | G2: mm | H2: na | I2: ma | J2: af | K2: am
B3: {=overview!C11&" / "&overview!C12} | C3: All | D3: Native Female | E3: Native Male | F3: Migrant Female | G3: Migrant Male | H3: Utility Native Male + Female | I3: Utility Migrant Male + Female | J3: Utility All Female | K3: Utility All Male | L3: Utility Other
B4: ⚠️ | C4: Do not add or delete lines until the next dark grey row below! The fields below are the fields used in other sheets and in the calculation. The address of these fields and their contents must remain always the same, so we can add calculations later!
B5: Population | C5: This is the base line of the caclution
A7: py | B7: Year of the count of the population | C7: 2024
A9: p00 | B9: 0 years | C9: 431230 | D9: 184942 | E9: 195688 | F9: 24645 | G9: 25955 | H9: {=E9+D9} | I9: {=G9+F9} | J9: {=D9+F9} | K9: {=E9+G9}
A10: p01 | B10: 1 years | C10: 448444 | D10: 192455 | E10: 204738 | F10: 24887 | G10: 26364 | H10: {=E10+D10} | I10: {=G10+F10} | J10: {=D10+F10} | K10: {=E10+G10}
A11: p02 | B11: 2 years | C11: 460121 | D11: 198642 | E11: 208930 | F11: 25697 | G11: 26852 | H11: {=E11+D11} | I11: {=G11+F11} | J11: {=D11+F11} | K11: {=E11+G11}
A12: p03 | B12: 3 years | C12: 471779 | D12: 201122 | E12: 213459 | F12: 27707 | G12: 29491 | H12: {=E12+D12} | I12: {=G12+F12} | J12: {=D12+F12} | K12: {=E12+G12}
A13: p04 | B13: 4 years | C13: 491416 | D13: 210212 | E13: 221288 | F13: 29069 | G13: 30847 | H13: {=E13+D13} | I13: {=G13+F13} | J13: {=D13+F13} | K13: {=E13+G13}
A14: p05 | B14: 5 years | C14: 511769 | D14: 218688 | E14: 231752 | F14: 29698 | G14: 31631 | H14: {=E14+D14} | I14: {=G14+F14} | J14: {=D14+F14} | K14: {=E14+G14}
A15: p06 | B15: 6 years | C15: 532902 | D15: 227751 | E15: 241613 | F15: 30741 | G15: 32797 | H15: {=E15+D15} | I15: {=G15+F15} | J15: {=D15+F15} | K15: {=E15+G15}
A16: p07 | B16: 7 years | C16: 546389 | D16: 235369 | E16: 248294 | F16: 30153 | G16: 32573 | H16: {=E16+D16} | I16: {=G16+F16} | J16: {=D16+F16} | K16: {=E16+G16}
A17: p08 | B17: 8 years | C17: 557631 | D17: 240818 | E17: 255000 | F17: 29841 | G17: 31972 | H17: {=E17+D17} | I17: {=G17+F17} | J17: {=D17+F17} | K17: {=E17+G17}
A18: p09 | B18: 9 years | C18: 572187 | D18: 247842 | E18: 262545 | F18: 29953 | G18: 31847 | H18: {=E18+D18} | I18: {=G18+F18} | J18: {=D18+F18} | K18: {=E18+G18}
A19: p10 | B19: 10 years | C19: 577620 | D19: 251495 | E19: 266331 | F19: 28927 | G19: 30867 | H19: {=E19+D19} | I19: {=G19+F19} | J19: {=D19+F19} | K19: {=E19+G19}
A20: p11 | B20: 11 years | C20: 600403 | D20: 262271 | E20: 277888 | F20: 28942 | G20: 31302 | H20: {=E20+D20} | I20: {=G20+F20} | J20: {=D20+F20} | K20: {=E20+G20}
... A108: p99 | B108: 99 years and older | C108: 35442 | D108: 28791 | E108: 6259 | F108: 262 | G108: 130 | H108: {=E108+D108} | I108: {=G108+F108} | J108: {=D108+F108} | K108: {=E108+G108}
A109: pt | B109: Total | C109: 64224888 | D109: 30124502 | E109: 28846728 | F109: 2651008 | G109: 2602650 | H109: {=SUM(H9:H108)} | I109: {=SUM(I9:I108)} | J109: {=D109+F109} | K109: {=E109+G109}
A111: ps | B111: Source of the data (verbal) | C111: https://esploradati.istat.it/databrowser/#/en/dw/categories/IT1,POP,1.0 https://demo.istat.it/app/?i=STR&a=2024&l=en; downloaded 46115; foreigners (=citizenship)
B112: URLs, where the data was found | C112: https://data.statistik.gv.at/data/OGD_bevstandjbab2002_BevStand_2025.csv, https://www.statistik.at/fileadmin/pages/435/Tabellensammlung_Migrationshintergrund_2025.ods
B113: Date, when the data was downloaded | C113: 2026-05-20
B114: Manual remarks (not for AI!)
B115: Remarks of the AI (e.g. calculation) | C115: Bevölkerung zum Stichtag 01.01.2025. Einzelalter × Geschlecht aus STAT OGD-Würfel OGD_bevstandjbab2002_BevStand_2025 (POPREG, ZMR-basiert), aggregiert über alle Gemeinden (Datei OGD_bevstandjbab2002_BevStand_2025.csv, Aggregation per Skript scripts/04_aggregate_pop.py, Total male=4.532.880, female=4.664.333, gesamt=9.197.213). Migrationshintergrund-Anteil aus STAT Mikrozensus-Arbeitskräfteerhebung Jahresdurchschnitt 2025 (Tabellensammlung_Migrationshintergrund_2025.ods, Tabelle A1, Sektion 'Alter, Geschlecht'). MH-Anteile pro 5-Jahres-Altersgruppe × Geschlecht auf POPREG-Einzelalter angewendet (annahme: konstante MH-Quote innerhalb der Gruppe). MH-Definition: i.w.S. (beide Elternteile im Ausland geboren), inkl. 1. und 2. Generation. Approximations-Caveats: (a) Mikrozensus-Basis = Privathaushalte (9.043.700), POPREG = inkl. Anstaltsbevölkerung (9.197.213, Diff. ca. 153.500 = 1,7%); Anstaltsbevölkerung wird hier implizit als Native gerechnet (MH-Anteil dort unbekannt, vermutlich niedriger). (b) Mikrozensus = Jahresdurchschnitt 2025, POPREG = Stichtag 01.01.2025; leichte Zeitinkonsistenz.
B116: Internal remarks
B118: ✏️ | C118: Enter your data below and make sure that you adjust the formulas above, if necessary. If calculations are necessary, use the fields below for it and use formulas in the area above, to fill in the fields above exactly as intended.
B119: Population | C119: Calculation of the population
B121: 0 years | D121: 25915 | E121: 28009 | F121: 10804 | G121: 10978
B122: 1 years | D122: 26754 | E122: 28927 | F122: 11153 | G122: 11337
B123: 2 years | D123: 28913 | E123: 31157 | F123: 12054 | G123: 12212
B124: 3 years | D124: 30795 | E124: 32953 | F124: 12838 | G124: 12915
B125: 4 years | D125: 30175 | E125: 32410 | F125: 12579 | G125: 12702
B126: 5 years | D126: 30724 | E126: 32794 | F126: 12808 | G126: 12853
B127: 6 years | D127: 31243 | E127: 33386 | F127: 13025 | G127: 13085
B128: 7 years | D128: 31602 | E128: 34308 | F128: 13175 | G128: 13447
B129: 8 years | D129: 31962 | E129: 34393 | F129: 13324 | G129: 13480
B130: 9 years | D130: 30951 | E130: 33517 | F130: 12903 | G130: 13137
B131: 10 years | D131: 30866 | E131: 33433 | F131: 12868 | G131: 13103
B132: 11 years | D132: 30104 | E132: 32584 | F132: 12550 | G132: 12771
...

Sheet births
A1: births
C2: aa | D2: nf | E2: nm | F2: mf | G2: mm | H2: na | I2: ma | J2: af | K2: am
B3: {=overview!C11&" / "&overview!C12} | C3: All | D3: Native Female | E3: Native Male | F3: Migrant Female | G3: Migrant Male | H3: Utility Native Male + Female | I3: Utility Migrant Male + Female | J3: Utility All Female | K3: Utility All Male | L3: Utility Other
B4: ⚠️ | C4: Do not add or delete lines until the next dark grey row below! The fields below are the fields used in other sheets and in the calculation. The address of these fields and their contents must remain always the same, so we can add calculations later!
B5: Fertility | C5: The values in this section are used to calculate the number of births in the population goups
A7: f | B7: Official fertility rate | D7: 0.53933116 | E7: 0.57066884 | F7: 0.54063142 | G7: 0.56936858
B8: Population of age 0 (=births) | C8: {=population!C9} | D8: {=population!D9} | E8: {=population!E9} | F8: {=population!F9} | G8: {=population!G9} | H8: {=population!H9} | I8: {=population!I9} | J8: {=population!J9} | K8: {=population!K9}
B9: Population of women of age 15-49 | D9: {=SUM(population!D24:D58)} | F9: {=SUM(population!F24:F58)}
B10: Factor: fertile women x fertility rate | C10: {=D10+F10} | D10: {=D9*D7} | F10: {=F9*F7}
A11: f00 | B11: Calculated births by fertility rate | C11: {=H11+I11} | D11: {=(D8+F8)*D10/C10} | E11: {=(E8+G8)*D10/C10} | F11: {=(D8+F8)*F10/C10} | G11: {=(E8+G8)*F10/C10} | H11: {=E11+D11} | I11: {=G11+F11} | J11: {=D11+F11} | K11: {=E11+G11}
A13: fs | B13: Source of the data (verbal) | C13: https://www.istat.it/en/press-release/births-and-fertility-of-the-resident-population-year-2024/ 1,79 for foreigners https://www.istat.it/en/press-release/births-and-fertility-of-the-resident-population-year-2024/; downloaded 46158
B14: URLs, where the data was found | C14: https://www.statistik.at/fileadmin/pages/410/Kap_H_Fertilitaet_2024.ods, https://www.statistik.at/statistiken/bevoelkerung-und-soziales/bevoelkerung/demographische-indikatoren-und-tafeln/demographische-querschnittsindikatoren, https://www.statistik.at/fileadmin/announcement/2025/02/20250226Geburtenbilanz2024.pdf
B15: Date, when the data was downloaded | C15: 2026-05-20
B16: Manual remarks (not for AI!)
B17: Remarks of the AI (e.g. calculation) | C17: TFR-Werte aus STAT Demographische Indikatoren Kapitel H Fertilität, Berichtsjahr 2024 (Datei Kap_H_Fertilitaet_2024.ods), Tabelle H9 'Gesamtfertilitätsrate nach Staatsangehörigkeit bzw. Herkunft der Mutter und Bundesländern', Zeile 'Österreich' (Spalte B): Frauen mit österr. Staatsangehörigkeit 1,216; Frauen mit nichtösterr. Staatsangehörigkeit 1,578. Methodische Approximation (CLAUDE.md §Fertilität): TFR-Migrant nach Staatsangehörigkeit (= Ausländer) wird auf gesamte Migrant-Population mit MH i.w.S. inkl. 2. Generation eingebürgert angewendet. Tendenz: TFR-Migrant-MH-i.w.S. liegt vermutlich leicht NIEDRIGER als 1,578 (2. Generation eingebürgert hat oft TFR näher an Native), d.h. Migrant-Geburten werden mit dieser Approximation leicht überschätzt. Cross-Check: TFR nach Herkunft (Tabelle H9 Zeile 'Frauen österr./nichtösterr. Herkunft') = 1,213/1,547 — sehr ähnliche Werte. TFR Insgesamt AT 2024 = 1,311 (laut H9 Zeile 'Insgesamt').
B18: Internal remarks
B20: Births | C20: The values in this section are used to calculate at which age of the mother the children are born
A22: b15 | B22: 15 years and younger age of the mother | C22: {=D22+E22+F22+G22} | D22: {=D$11*$H22/$H$57} | E22: {=E$11*$H22/$H$57} | F22: {=F$11*$I22/$I$57} | G22: {=G$11*$I22/$I$57} | H22: {=H74} | I22: {=I74} | J22: {=D22+F22} | K22: {=E22+G22}
A23: b16 | B23: 16 years age of the mother | C23: 2981.8338 | D23: 1278.8217 | E23: 1353.1273 | F23: 170.41322 | G23: 179.4715 | H23: {=H75} | I23: {=I75} | J23: {=D23+F23} | K23: {=E23+G23}
A24: b17 | B24: 17 years age of the mother | C24: 3587.8018 | D24: 1538.7038 | E24: 1628.1097 | F24: 205.04458 | G24: 215.94369 | H24: {=H76} | I24: {=I76} | J24: {=D24+F24} | K24: {=E24+G24}
A25: b18 | B25: 18 years age of the mother | C25: 4273.9603 | D25: 1832.9772 | E25: 1939.4818 | F25: 244.25887 | G25: 257.2424 | H25: {=H77} | I25: {=I77} | J25: {=D25+F25} | K25: {=E25+G25}
A26: b19 | B26: 19 years age of the mother | C26: 5040.685 | D26: 2161.8031 | E26: 2287.414 | F26: 288.07755 | G26: 303.39025 | H26: {=H78} | I26: {=I78} | J26: {=D26+F26} | K26: {=E26+G26}
A27: b20 | B27: 20 years age of the mother | C27: 5885.802 | D27: 2524.2492 | E27: 2670.92 | F27: 336.37639 | G27: 354.25641 | H27: {=H79} | I27: {=I79} | J27: {=D27+F27} | K27: {=E27+G27}
A28: b21 | B28: 21 years age of the mother | C28: 6804.2266 | D28: 2918.1348 | E28: 3087.6922 | F28: 388.86479 | G28: 409.53482 | H28: {=H80} | I28: {=I80} | J28: {=D28+F28} | K28: {=E28+G28}
A29: b22 | B29: 22 years age of the mother | C29: 7787.6947 | D29: 3339.9157 | E29: 3533.9805 | F29: 445.07046 | G29: 468.72809 | H29: {=H81} | I29: {=I81} | J29: {=D29+F29} | K29: {=E29+G29}
A30: b23 | B30: 23 years age of the mother | C30: 8824.6216 | D30: 3784.6234 | E30: 4004.5279 | F30: 504.33133 | G30: 531.13896 | H30: {=H82} | I30: {=I82} | J30: {=D30+F30} | K30: {=E30+G30}
A31: b24 | B31: 24 years age of the mother | C31: 9900.1162 | D31: 4245.8718 | E31: 4492.5769 | F31: 565.79636 | G31: 595.87115 | H31: {=H83} | I31: {=I83} | J31: {=D31+F31} | K31: {=E31+G31}
A32: b25 | B32: 25 years age of the mother | C32: 10996.172 | D32: 4715.9381 | E32: 4989.9563 | F32: 628.43646 | G32: 661.84087 | H32: {=H84} | I32: {=I84} | J32: {=D32+F32} | K32: {=E32+G32}
A33: b26 | B33: 26 years age of the mother | C33: 12092.045 | D33: 5185.9264 | E33: 5487.2531 | F33: 691.06615 | G33: 727.79964 | H33: {=H85} | I33: {=I85} | J33: {=D33+F33} | K33: {=E33+G33}
A34: b27 | B34: 27 years age of the mother | C34: 13164.824 | D34: 5646.0098 | E34: 5974.0695 | F34: 752.37594 | G34: 792.36833 | H34: {=H86} | I34: {=I86} | J34: {=D34+F34} | K34: {=E34+G34}
... A56: b49 | B56: 49 years and older age of the mother | C56: 6804.2266 | D56: 2918.1348 | E56: 3087.6922 | F56: 388.86479 | G56: 409.53482 | H56: {=H108} | I56: {=I108} | J56: {=D56+F56} | K56: {=E56+G56}
A57: bt | B57: Total | C57: {=SUM(C22:C56)} | D57: {=SUM(D22:D56)} | E57: {=SUM(E22:E56)} | F57: {=SUM(F22:F56)} | G57: {=SUM(G22:G56)} | H57: {=SUM(H22:H56)} | I57: {=SUM(I22:I56)} | J57: {=SUM(J22:J56)} | K57: {=SUM(K22:K56)}
A59: bs | B59: Source of the data (verbal) | C59: {=IF(C60="","?",C60)&IF(C61="","","; downloaded "&C61)&IF(C62="","","; "&C62)}
B60: URLs, where the data was found | C60: Quelle wie Fertility-Sektion oben, siehe C14. https://www.statistik.at/fileadmin/pages/410/Kap_H_Fertilitaet_2024.ods, https://www.statistik.at/statistiken/bevoelkerung-und-soziales/bevoelkerung/demographische-indikatoren-und-tafeln/demographische-querschnittsindikatoren, https://www.statistik.at/fileadmin/announcement/2025/02/20250226Geburtenbilanz2024.pdf
B61: Date, when the data was downloaded | C61: 2026-05-20
B62: Manual remarks (not for AI!)
B63: Remarks of the AI (e.g. calculation) | C63: Altersspezifische Aufschlüsselung der Geburten pro Alter × NAT/MIG (H74:H108 = Native total, I74:I108 = Migrant total) aus STAT Tabelle H6 'Altersspezifische Fertilitätsraten nach Staatsangehörigkeitsgruppen' (Kap_H_Fertilitaet_2024.ods), Spalten 3 (Native = Frauen mit österr. Staatsangehörigkeit) und 4 (Migrant = nicht-österr.) — ASFR pro 1000 Frauen × Population per Einzelalter (Native: pop.D[121+age], Migrant: pop.F[121+age]) → absolute Geburten pro Alter × NAT/MIG. Sex-Aufteilung in Display-Zeilen 22-56 erfolgt via Vorlagen-Formel D22/E22 = D11/E11 × H22/H57 (distribuiert Total-Native-Geburten anteilig). Cross-Check: ASFR-Sum Native 1.215,7 (Referenz H9: 1.216), ASFR-Sum Migrant 1.578,3 (Referenz H9: 1.578) — exakte Übereinstimmung mit TFR. Die Default-Vorlagen-Kurve L74:L108 (symmetrisch, Peak Alter 32) wird durch H/I überschrieben — H/I sind genauere AT-2024-Daten (Migrant peakt früher bei 25-30, Native bei 32). Methodisch identisch zur TFR-Approximation oben (Staatsangehörigkeit auf MH i.w.S. angewendet). Quelle wie Fertility-Sektion oben (Kap_H_Fertilitaet_2024.ods), siehe C14.
B64: Internal remarks
B66: ✏️ | C66: Enter your data below and make sure that you adjust the formulas above, if necessary. If calculations are necessary, use the fields below for it and use formulas in the area above, to fill in the fields above exactly as intended.
B67: Births | C67: Calculation of the births
...

Sheet deaths
A1: deaths
C2: aa | D2: nf | E2: nm | F2: mf | G2: mm | H2: na | I2: ma | J2: af | K2: am
B3: {=overview!C11&" / "&overview!C12} | C3: All | D3: Native Female | E3: Native Male | F3: Migrant Female | G3: Migrant Male | H3: Utility Native Male + Female | I3: Utility Migrant Male + Female | J3: Utility All Female | K3: Utility All Male | L3: Utility Other
B4: ⚠️ | C4: Do not add or delete lines until the next dark grey row below! The fields below are the fields used in other sheets and in the calculation. The address of these fields and their contents must remain always the same, so we can add calculations later!
B5: Deaths | C5: This table is needed to calculate the Leslie matrix
A7: d00 | B7: 0 years age of the deceased | C7: 222.8 | D7: 78.8 | E7: 105.4 | F7: 18 | G7: 20.6 | H7: {=E7+D7} | I7: {=G7+F7} | J7: {=D7+F7} | K7: {=E7+G7}
A8: d01 | B8: 1 years age of the deceased | C8: 222.8 | D8: 78.8 | E8: 105.4 | F8: 18 | G8: 20.6 | H8: {=E8+D8} | I8: {=G8+F8} | J8: {=D8+F8} | K8: {=E8+G8}
A9: d02 | B9: 2 years age of the deceased | C9: 222.8 | D9: 78.8 | E9: 105.4 | F9: 18 | G9: 20.6 | H9: {=E9+D9} | I9: {=G9+F9} | J9: {=D9+F9} | K9: {=E9+G9}
A10: d03 | B10: 3 years age of the deceased | C10: 222.8 | D10: 78.8 | E10: 105.4 | F10: 18 | G10: 20.6 | H10: {=E10+D10} | I10: {=G10+F10} | J10: {=D10+F10} | K10: {=E10+G10}
A11: d04 | B11: 4 years age of the deceased | C11: 222.8 | D11: 78.8 | E11: 105.4 | F11: 18 | G11: 20.6 | H11: {=E11+D11} | I11: {=G11+F11} | J11: {=D11+F11} | K11: {=E11+G11}
A12: d05 | B12: 5 years age of the deceased | C12: 33.6 | D12: 13.6 | E12: 12.4 | F12: 4.2 | G12: 3.4 | H12: {=E12+D12} | I12: {=G12+F12} | J12: {=D12+F12} | K12: {=E12+G12}
A13: d06 | B13: 6 years age of the deceased | C13: 33.6 | D13: 13.6 | E13: 12.4 | F13: 4.2 | G13: 3.4 | H13: {=E13+D13} | I13: {=G13+F13} | J13: {=D13+F13} | K13: {=E13+G13}
A14: d07 | B14: 7 years age of the deceased | C14: 33.6 | D14: 13.6 | E14: 12.4 | F14: 4.2 | G14: 3.4 | H14: {=E14+D14} | I14: {=G14+F14} | J14: {=D14+F14} | K14: {=E14+G14}
A15: d08 | B15: 8 years age of the deceased | C15: 33.6 | D15: 13.6 | E15: 12.4 | F15: 4.2 | G15: 3.4 | H15: {=E15+D15} | I15: {=G15+F15} | J15: {=D15+F15} | K15: {=E15+G15}
A16: d09 | B16: 9 years age of the deceased | C16: 33.6 | D16: 13.6 | E16: 12.4 | F16: 4.2 | G16: 3.4 | H16: {=E16+D16} | I16: {=G16+F16} | J16: {=D16+F16} | K16: {=E16+G16}
A17: d10 | B17: 10 years age of the deceased | C17: 44 | D17: 18.4 | E17: 19.2 | F17: 1.6 | G17: 4.8 | H17: {=E17+D17} | I17: {=G17+F17} | J17: {=D17+F17} | K17: {=E17+G17}
A18: d11 | B18: 11 years age of the deceased | C18: 44 | D18: 18.4 | E18: 19.2 | F18: 1.6 | G18: 4.8 | H18: {=E18+D18} | I18: {=G18+F18} | J18: {=D18+F18} | K18: {=E18+G18}
... A106: d99 | B106: 99 years and older age of the deceased | C106: 12121.2 | D106: 9030 | E106: 3054.6 | F106: 28.2 | G106: 8.4 | H106: {=E106+D106} | I106: {=G106+F106} | J106: {=D106+F106} | K106: {=E106+G106}
A107: dt | B107: Total | C107: {=SUM(C7:C106)} | D107: {=SUM(D7:D106)} | E107: {=SUM(E7:E106)} | F107: {=SUM(F7:F106)} | G107: {=SUM(G7:G106)} | H107: {=SUM(H7:H106)} | I107: {=SUM(I7:I106)} | J107: {=D107+F107} | K107: {=E107+G107}
A109: ds | B109: Source of the data (verbal) | C109: https://esploradati.istat.it/databrowser/#/en/dw/categories/IT1,POP,1.0/POP_MORTALITY/DCIS_DECESSI/IT1,26_29_DF_DCIS_DECESSI_2,1.0; downloaded 46115; the data is available only in 5 year batches, so we calculated the numbers per age by dividing the batches
B110: URLs, where the data was found | C110: https://www.statistik.at/statistiken/bevoelkerung-und-soziales/bevoelkerung/gestorbene/demographische-merkmale-von-gestorbenen, https://www.statistik.at/fileadmin/pages/428/neu_Gestorbene__nach__demographischen__Merkmalen.ods
B111: Date, when the data was downloaded | C111: 2026-05-20
B112: Manual remarks (not for AI!)
B113: Remarks of the AI (e.g. calculation) | C113: Gestorbene 2024 Einzelalter nach Geschlecht aus STAT 'Gestorbene nach demographischen Merkmalen' (Datei neu_Gestorbene_nach_demographischen_Merkmalen.ods), Tabelle_11 'Gestorbene nach Altersjahr, Familienstand und Geschlecht 2024', Spalten 2 (Männer) und 3 (Frauen) der Total-Spalte 'Gestorbene insgesamt'. Altersgruppen 'Unter 1' → Alter 0, 'X bis unter X+1' → Alter X, '99-110+' aggregiert auf Alter 99+. Total male=44036 (STAT: 44.036), female=44450 (STAT: 44.450). NAT/MIG-Split (CLAUDE.md §Sterbe): anteilig zur Pop-Struktur pro Alter × Geschlecht (deaths_native = deaths_total × pop_native / pop_total). Annahme: einheitliche Sterbetafel für Native und Migrant — ignoriert den Healthy-Migrant-Effekt (jüngere Migranten haben in Realität günstigere Sterbestatistik) und ggf. ungünstigere Sterbestatistik in Hochaltrigengruppen. STAT publiziert Sterbefälle nicht standardmäßig nach MH i.w.S. (Tabelle 8 hat Geburtsland AT/EU/sonstige, aber nicht auf MH-Definition mappbar). Aggregat-Sums: Native-F 36695, Native-M 36362, Migrant-F 7755, Migrant-M 7674.
B114: Internal remarks
B116: ✏️ | C116: Enter your data below and make sure that you adjust the formulas above, if necessary. If calculations are necessary, use the fields below for it and use formulas in the area above, to fill in the fields above exactly as intended.
B117: Deaths | C117: Calculation of the deaths
B119: 0 years | D119: 79 | E119: 89 | F119: 33 | G119: 35
B120: 1 years | D120: 5 | E120: 6 | F120: 2 | G120: 2
B121: 2 years | D121: 4 | E121: 2 | F121: 1 | G121: 1
B122: 3 years | D122: 4 | E122: 6 | F122: 1 | G122: 3
B123: 4 years | D123: 1 | E123: 3 | F123: 1 | G123: 1
B124: 5 years | D124: 3 | E124: 6 | F124: 1 | G124: 2
B125: 6 years | D125: 3 | E125: 4 | F125: 1 | G125: 1
B126: 7 years | D126: 3 | E126: 4 | F126: 1 | G126: 2
B127: 8 years | D127: 1 | E127: 1 | F127: 1 | G127: 1
B128: 9 years | D128: 2 | E128: 1 | F128: 1 | G128: 1
B129: 10 years | D129: 2 | E129: 1 | F129: 1 | G129: 1
B130: 11 years | D130: 0 | E130: 1 | F130: 0 | G130: 1
... B218: 99 years and older | D218: 1041 | E218: 206 | F218: 206 | G218: 38

Sheet migration
A1: migration
C2: aa | D2: nf | E2: nm | F2: mf | G2: mm | H2: na | I2: ma | J2: af | K2: am
B3: {=overview!C11&" / "&overview!C12} | C3: All | D3: Native Female | E3: Native Male | F3: Migrant Female | G3: Migrant Male | H3: Utility Native Male + Female | I3: Utility Migrant Male + Female | J3: Utility All Female | K3: Utility All Male | L3: Utility Other
B4: ⚠️ | C4: Do not add or delete lines until the next dark grey row below! The fields below are the fields used in other sheets and in the calculation. The address of these fields and their contents must remain always the same, so we can add calculations later!
B5: Migration balance | C5: This is the total of immigrations (into the country) minus emigration (out of the country)
B7: Year of the last migration numbers | C7: 2024
A9: ma | B9: Avarage migration balance (10 years) | C9: 184624 | D9: -27092.4 | E9: -31884.1 | F9: 106875.2 | G9: 136725.3 | H9: {=E9+D9} | I9: {=G9+F9} | J9: {=D9+F9} | K9: {=E9+G9}
A11: m00 | B11: 0 years | C11: 0 | D11: 0 | E11: 0 | F11: 0 | G11: 0 | H11: {=E11+D11} | I11: {=G11+F11} | J11: {=D11+F11} | K11: {=E11+G11}
A12: m01 | B12: 1 years | C12: 0 | D12: 0 | E12: 0 | F12: 0 | G12: 0 | H12: {=E12+D12} | I12: {=G12+F12} | J12: {=D12+F12} | K12: {=E12+G12}
A13: m02 | B13: 2 years | C13: 0 | D13: 0 | E13: 0 | F13: 0 | G13: 0 | H13: {=E13+D13} | I13: {=G13+F13} | J13: {=D13+F13} | K13: {=E13+G13}
A14: m03 | B14: 3 years | C14: 0 | D14: 0 | E14: 0 | F14: 0 | G14: 0 | H14: {=E14+D14} | I14: {=G14+F14} | J14: {=D14+F14} | K14: {=E14+G14}
A15: m04 | B15: 4 years | C15: 0 | D15: 0 | E15: 0 | F15: 0 | G15: 0 | H15: {=E15+D15} | I15: {=G15+F15} | J15: {=D15+F15} | K15: {=E15+G15}
A16: m05 | B16: 5 years | C16: 0 | D16: 0 | E16: 0 | F16: 0 | G16: 0 | H16: {=E16+D16} | I16: {=G16+F16} | J16: {=D16+F16} | K16: {=E16+G16} | L16: 0.0001247127
A17: m06 | B17: 6 years | C17: 1276.6229 | D17: -187.3363 | E17: -220.46955 | F17: 739.01185 | G17: 945.41687 | H17: {=E17+D17} | I17: {=G17+F17} | J17: {=D17+F17} | K17: {=E17+G17} | L17: 0.0002035291
A18: m07 | B18: 7 years | C18: 1536.0581 | D18: -225.40677 | E18: -265.27336 | F18: 889.19378 | G18: 1137.5444 | H18: {=E18+D18} | I18: {=G18+F18} | J18: {=D18+F18} | K18: {=E18+G18} | L18: 0.000325446
A19: m08 | B19: 8 years | C19: 1829.8255 | D19: -268.51528 | E19: -316.00626 | F19: 1059.25 | G19: 1355.0971 | H19: {=E19+D19} | I19: {=G19+F19} | J19: {=D19+F19} | K19: {=E19+G19} | L19: 0.0005098804
A20: m09 | B20: 9 years | C20: 2158.086 | D20: -316.68542 | E20: -372.69602 | F20: 1249.2735 | G20: 1598.1939 | H20: {=E20+D20} | I20: {=G20+F20} | J20: {=D20+F20} | K20: {=E20+G20} | L20: 0.0007826985
A21: m10 | B21: 10 years | C21: 2519.9089 | D21: -369.78063 | E21: -435.18192 | F21: 1458.7257 | G21: 1866.1458 | H21: {=E21+D21} | I21: {=G21+F21} | J21: {=D21+F21} | K21: {=E21+G21} | L21: 0.0011772198
A22: m11 | B22: 11 years | C22: 2913.1172 | D22: -427.48146 | E22: -503.08801 | F22: 1686.3462 | G22: 2157.3405 | H22: {=E22+D22} | I22: {=G22+F22} | J22: {=D22+F22} | K22: {=E22+G22} | L22: 0.0017348322
A23: m12 | B23: 12 years | C23: 3334.1728 | D23: -489.2687 | E23: -575.80325 | F23: 1930.087 | G23: 2469.1577 | H23: {=E23+D23} | I23: {=G23+F23} | J23: {=D23+F23} | K23: {=E23+G23} | L23: 0.002504922
A24: m13 | B24: 13 years | C24: 3778.1159 | D24: -554.41453 | E24: -652.47111 | F24: 2187.077 | G24: 2797.9246 | H24: {=E24+D24} | I24: {=G24+F24} | J24: {=D24+F24} | K24: {=E24+G24} | L24: 0.0035437886
A25: m14 | B25: 14 years | C25: 4238.5712 | D25: -621.98341 | E25: -731.99057 | F25: 2453.6254 | G25: 3138.9197 | H25: {=E25+D25} | I25: {=G25+F25} | J25: {=D25+F25} | K25: {=E25+G25} | L25: 0.004912225
A26: m15 | B26: 15 years | C26: 4707.8293 | D26: -690.84406 | E26: -813.03026 | F26: 2725.2697 | G26: 3486.4339 | H26: {=E26+D26} | I26: {=G26+F26} | J26: {=D26+F26} | K26: {=E26+G26} | L26: 0.0066715315
A27: m16 | B27: 16 years | C27: 5177.0094 | D27: -759.69327 | E27: -894.0565 | F27: 2996.8689 | G27: 3833.8903 | H27: {=E27+D27} | I27: {=G27+F27} | J27: {=D27+F27} | K27: {=E27+G27} | L27: 0.0088778883
... A65: m54 | B65: 54 years | C65: 0 | D65: 0 | E65: 0 | F65: 0 | G65: 0 | H65: {=E65+D65} | I65: {=G65+F65} | J65: {=D65+F65} | K65: {=E65+G65} | L65: 0.0001247127
A66: m55 | B66: 55 years | C66: 0 | D66: 0 | E66: 0 | F66: 0 | G66: 0 | H66: {=E66+D66} | I66: {=G66+F66} | J66: {=D66+F66} | K66: {=E66+G66}
A67: m56 | B67: 56 years | C67: 0 | D67: 0 | E67: 0 | F67: 0 | G67: 0 | H67: {=E67+D67} | I67: {=G67+F67} | J67: {=D67+F67} | K67: {=E67+G67}
A68: m57 | B68: 57 years | C68: 0 | D68: 0 | E68: 0 | F68: 0 | G68: 0 | H68: {=E68+D68} | I68: {=G68+F68} | J68: {=D68+F68} | K68: {=E68+G68}
A69: m58 | B69: 58 years | C69: 0 | D69: 0 | E69: 0 | F69: 0 | G69: 0 | H69: {=E69+D69} | I69: {=G69+F69} | J69: {=D69+F69} | K69: {=E69+G69}
A70: m59 | B70: 59 years | C70: 0 | D70: 0 | E70: 0 | F70: 0 | G70: 0 | H70: {=E70+D70} | I70: {=G70+F70} | J70: {=D70+F70} | K70: {=E70+G70}
A71: m60 | B71: 60 years | C71: 0 | D71: 0 | E71: 0 | F71: 0 | G71: 0 | H71: {=E71+D71} | I71: {=G71+F71} | J71: {=D71+F71} | K71: {=E71+G71}
A72: m61 | B72: 61 years | C72: 0 | D72: 0 | E72: 0 | F72: 0 | G72: 0 | H72: {=E72+D72} | I72: {=G72+F72} | J72: {=D72+F72} | K72: {=E72+G72}
A73: m62 | B73: 62 years | C73: 0 | D73: 0 | E73: 0 | F73: 0 | G73: 0 | H73: {=E73+D73} | I73: {=G73+F73} | J73: {=D73+F73} | K73: {=E73+G73}
A74: m63 | B74: 63 years | C74: 0 | D74: 0 | E74: 0 | F74: 0 | G74: 0 | H74: {=E74+D74} | I74: {=G74+F74} | J74: {=D74+F74} | K74: {=E74+G74}
A75: m64 | B75: 64 years | C75: 0 | D75: 0 | E75: 0 | F75: 0 | G75: 0 | H75: {=E75+D75} | I75: {=G75+F75} | J75: {=D75+F75} | K75: {=E75+G75}
A76: m65 | B76: 65 years | C76: 0 | D76: 0 | E76: 0 | F76: 0 | G76: 0 | H76: {=E76+D76} | I76: {=G76+F76} | J76: {=D76+F76} | K76: {=E76+G76}
A77: m66 | B77: 66 years | C77: 0 | D77: 0 | E77: 0 | F77: 0 | G77: 0 | H77: {=E77+D77} | I77: {=G77+F77} | J77: {=D77+F77} | K77: {=E77+G77}
... A110: m99 | B110: 99 years and older | C110: 0 | D110: 0 | E110: 0 | F110: 0 | G110: 0 | H110: {=E110+D110} | I110: {=G110+F110} | J110: {=D110+F110} | K110: {=E110+G110}
A111: mt | B111: Total | C111: {=SUM(C11:C110)} | D111: {=SUM(D11:D110)} | E111: {=SUM(E11:E110)} | F111: {=SUM(F11:F110)} | G111: {=SUM(G11:G110)} | H111: {=SUM(H11:H110)} | I111: {=SUM(I11:I110)} | J111: {=D111+F111} | K111: {=E111+G111}
A113: ms | B113: Source of the data (verbal) | C113: https://ec.europa.eu/eurostat/databrowser/view/migr_imm1ctz__custom_21284776/default/table; downloaded 46146; we used the 10-year average number of migrants (2015-2024); not for all countries age-related data is available so the number of migrants is binomially distributed between the age of 6 and 44 (μ=25, σ=10)
...

Sheet origin
A1: origin
C2: aa | D2: nf | E2: nm | F2: mf | G2: mm | H2: na | I2: ma | J2: af | K2: am
B3: {=overview!C11&" / "&overview!C12} | C3: All | D3: Native Female | E3: Native Male | F3: Migrant Female | G3: Migrant Male | H3: Utility Native Male + Female | I3: Utility Migrant Male + Female | J3: Utility All Female | K3: Utility All Male | L3: Utility Other
B4: ✏️ | C4: Enter your data below and make sure that you adjust the formulas above, if necessary. If calculations are necessary, use the fields below for it and use formulas in the area above, to fill in the fields above exactly as intended.
B5: Origin of Migrants | C5: This table contains the countries the current migrants come from.
B7: Year of the numbers | C7: 2025
B9: Europe
A10: c1ad | B10: Andorra | C10: AD | F10: 5 | G10: 4 | I10: {=G10+F10}
A11: c1al | B11: Albania | C11: AL | F11: 202692 | G11: 213537 | I11: {=G11+F11}
A12: c1at | B12: Austria | C12: AT | F12: 4396 | G12: 2039 | I12: {=G12+F12}
A13: c1ax | B13: Åland Islands | C13: AX | I13: {=G13+F13}
A14: c1ba | B14: Bosnia and Herzegovina | C14: BA | F14: 9399 | G14: 10178 | I14: {=G14+F14}
A15: c1be | B15: Belgium | C15: BE | F15: 3492 | G15: 2784 | I15: {=G15+F15}
A16: c1bg | B16: Bulgaria | C16: BG | F16: 30155 | G16: 18504 | I16: {=G16+F16}
A17: c1by | B17: Belarus | C17: BY | F17: 7494 | G17: 2011 | I17: {=G17+F17}
A18: c1ch | B18: Switzerland | C18: CH | F18: 4487 | G18: 3307 | I18: {=G18+F18}
A19: c1cz | B19: Czechia[i] | C19: CZ | F19: 4432 | G19: 1026 | I19: {=G19+F19}
A20: c1de | B20: Germany | C20: DE | F20: 21563 | G20: 13541 | I20: {=G20+F20}
A21: c1dk | B21: Denmark | C21: DK | F21: 1150 | G21: 828 | I21: {=G21+F21}
A22: c1ee | B22: Estonia | C22: EE | F22: 1008 | G22: 224 | I22: {=G22+F22}
A23: c1es | B23: Spain | C23: ES | F23: 18819 | G23: 10113 | I23: {=G23+F23}
A24: c1fi | B24: Finland | C24: FI | F24: 1214 | G24: 379 | I24: {=G24+F24}
A25: c1fo | B25: Faroe Islands (the) | C25: FO | F25: 0 | G25: 1 | I25: {=G25+F25}
... A27: c1gb | B27: United Kingdom of Great Britain and Northern Ireland (the) | C27: GB | F27: 13602 | G27: 12600 | I27: {=G27+F27}
A28: c1gg | B28: Guernsey | C28: GG | I28: {=G28+F28}
A29: c1gi | B29: Gibraltar | C29: GI | F29: 4 | G29: 6 | I29: {=G29+F29}
A30: c1gr | B30: Greece | C30: GR | F30: 3949 | G30: 3651 | I30: {=G30+F30}
A31: c1hr | B31: Croatia | C31: HR | F31: 7879 | G31: 7470 | I31: {=G31+F31}
A32: c1hu | B32: Hungary | C32: HU | F32: 5852 | G32: 2207 | I32: {=G32+F32}
A33: c1ie | B33: Ireland | C33: IE | F33: 1982 | G33: 1971 | I33: {=G33+F33}
A34: c1im | B34: Isle of Man | C34: IM | I34: {=G34+F34}
A35: c1is | B35: Iceland | C35: IS | F35: 92 | G35: 78 | I35: {=G35+F35}
A36: c1it | B36: Italy | C36: IT | F36: 17547 | G36: 21330 | I36: {=G36+F36}
A37: c1je | B37: Jersey | C37: JE | I37: {=G37+F37}
A38: c1li | B38: Liechtenstein | C38: LI | F38: 13 | G38: 10 | I38: {=G38+F38}
A39: c1lt | B39: Lithuania | C39: LT | F39: 4243 | G39: 1049 | I39: {=G39+F39}
A40: c1lu | B40: Luxembourg | C40: LU | F40: 154 | G40: 138 | I40: {=G40+F40}
A41: c1lv | B41: Latvia | C41: LV | F41: 2324 | G41: 585 | I41: {=G41+F41}
A42: c1mc | B42: Monaco | C42: MC | F42: 14 | G42: 19 | I42: {=G42+F42}
A43: c1md | B43: Moldova (the Republic of) | C43: MD | F43: 68129 | G43: 34538 | I43: {=G43+F43}
...

Sheet patria
A1: patria
C2: aa | D2: nf | E2: nm | F2: mf | G2: mm | H2: na | I2: ma | J2: af | K2: am
B3: {=overview!C11&" / "&overview!C12} | C3: All | D3: Native Female | E3: Native Male | F3: Migrant Female | G3: Migrant Male | H3: Utility Native Male + Female | I3: Utility Migrant Male + Female | J3: Utility All Female | K3: Utility All Male | L3: Utility Other
B4: ✏️ | C4: Enter your data below and make sure that you adjust the formulas above, if necessary. If calculations are necessary, use the fields below for it and use formulas in the area above, to fill in the fields above exactly as intended.
B5: Naturalisation | C5: Fill in the numbers of people being naturalized in the specified year. This is not relevant for the calculation of version 1 but it is important for future versions.
B7: Year of the last migration numbers | C7: 2025
B9: {=$B10-1} | C9: {=I9} | I9: 39824
B10: {=$B11-1} | C10: {=I10} | I10: 38973
B11: {=$B12-1} | C11: {=I11} | I11: 29185
B12: {=$B13-1} | C12: {=I12} | I12: 20460
B13: {=$B14-1} | C13: {=I13} | I13: 22646
B14: {=$B15-1} | C14: {=I14} | I14: 40523
B15: {=$B16-1} | C15: {=I15} | I15: 35431
B16: {=$B17-1} | C16: {=I16} | I16: 20318
B17: {=$B18-1} | C17: {=I17} | I17: 8712
B18: {=$B19-1} | C18: {=I18} | I18: 7688
B19: {=$B20-1} | C19: {=I19} | I19: 6322
B20: {=$B21-1} | C20: {=I20} | I20: 6083
... B39: {=$B40-1} | C39: {=I39} | I39: 8176
B40: {=$B41-1} | C40: {=I40} | F40: 4832 | G40: 3147 | I40: {=G40+F40}
B41: {=$B42-1} | C41: {=I41} | F41: 4835 | G41: 2915 | I41: {=G41+F41}
B42: {=$B43-1} | C42: {=I42} | F42: 6404 | G42: 4495 | I42: {=G42+F42}
B43: {=$B44-1} | C43: {=I43} | F43: 4006 | G43: 4869 | I43: {=G43+F43}
B44: {=$B45-1} | C44: {=I44} | F44: 4025 | G44: 4463 | I44: {=G44+F44}
B45: {=$B46-1} | C45: {=I45} | F45: 4752 | G45: 5263 | I45: {=G45+F45}
B46: {=$B47-1} | C46: {=I46} | F46: 3955 | G46: 4157 | I46: {=G46+F46}
B47: {=$B48-1} | C47: {=I47} | F47: 4011 | G47: 4221 | I47: {=G47+F47}
B48: {=$B49-1} | C48: {=I48} | F48: 4305 | G48: 4165 | I48: {=G48+F48}
B49: {=$B50-1} | C49: {=I49} | F49: 4704 | G49: 4494 | I49: {=G49+F49}
B50: {=$B51-1} | C50: {=I50} | F50: 5685 | G50: 5709 | I50: {=G50+F50}
B51: {=$B52-1} | C51: {=I51} | F51: 6033 | G51: 5887 | I51: {=G51+F51}
... B83: {=$B84-1} | C83: {=I83} | F83: 6479 | G83: 6557 | I83: {=G83+F83}
B84: {=$C$7} | C84: {=I84} | I84: {=G84+F84}
C85: {=SUM(C9:C84)} | F85: {=SUM(F9:F84)} | G85: {=SUM(G9:G84)} | I85: {=SUM(I9:I84)}
B87: Source of the data (verbal) | C87: {=IF(C88="","?",C88)&IF(C89="","","; downloaded "&C89)&IF(C90="","","; "&C90)}
B88: URLs, where the data was found | C88: https://ec.europa.eu/eurostat/databrowser/view/migr_acq, https://data.statistik.gv.at/data/OGD_einbuergerungen_EINBJ_1.csv, https://www.statistik.at/fileadmin/pages/436/neu_Einbuergerungen.ods
B89: Date, when the data was downloaded | C89: 2026-05-20
B90: Manual remarks (not for AI!)
B91: Remarks of the AI (e.g. calculation) | C91: Naturalisationen 2008-2024 aus EUROSTAT migr_acq (Acquisition of citizenship by sex, age, former citizenship), geo=AT, citizen=TOTAL, age=TOTAL — zählt nur in Österreich resident Eingebürgerte. Jahre 1981-2007 aus STAT OGD-Würfel OGD_einbuergerungen_EINBJ_1 (Berichtsjahr × Geburtsland × Altersgruppe × Geschlecht) — Total inkl. Auslandseinbürgerungen; Ausland-Anteil pre-2008 historisch <10 % (vgl. STAT Tabelle 2 'Inland' vs 'Ausland'). Methodenbruch 2007/2008: ab 2008 nur AT-resident (Eurostat), davor inkl. Ausland (OGD). Effekt minimal pre-2014 (Diff <1 % der Werte); 1985 Ausland-Anteil 13,9 %. Jahre 1946-1980 (35 Jahre): kein Sex-Split in STAT-Open-Data publiziert. STAT Tabelle 2 hat Totals ohne Geschlecht 1946-2024; OGD_einbuergerungen startet bei 1981. Bewusst leer (User-Vorgabe: keine 50/50-Approximation). Jahr 2025 leer. STAT 2025 enthält §58c-Auslands-Einbürgerungen (Nazi-Opfer-Nachfahren-Anzeige, ca. 40 % der 25.095 Gesamteinbürgerungen 2025 — nicht relevant für das AT-resident Modell). Eurostat 2025 noch nicht publiziert (Stand Mai 2026). Cross-Check 2024: Eurostat 13.036 (AT-resident), STAT/OGD 21.891 (Total inkl. 8.855 Ausland §58c). Methodisch (CLAUDE.md §Pass-Wechsel): Naturalisation nur Migrant F (col F) + Migrant M (col G); Native bleibt leer. V3-Ergänzung 2026-05-21: Naturalisation 1950-1980 (31 Jahre) nachgepflegt aus STAT Tabelle 2 'Eingebürgerte Personen seit 1946' (neu_Einbuergerungen.ods), Spalte 'Österreich(Inland)'. Total pro Jahr direkt in Spalte I (Utility Migrant M+F) wegen fehlendem Sex-Split in STAT-Open-Data vor 1981; F/G dieser Jahre leer. Originalformel I=G+F damit überschrieben (nur für 1950-1980; 1981+ behält Sex-Split-Konvention). §58c-äquivalente Auslandseinbürgerungen (Spalte 'Ausland' in T2, sporadisch ab 1966) bewusst exkludiert — resident-only-Logik konsistent mit V2-Wahl für 2008+ (Eurostat). Jahre 1946-1949 außerhalb Template-Range (B9..B84 = 1950..2025); nicht aggregiert. Summe 1950-1980 = 381.150.
B92: Internal remarks
...

Sheet export
A1: export
C2: aa | D2: nf | E2: nm | F2: mf | G2: mm | H2: na | I2: ma | J2: af | K2: am
B3: {=overview!C11&" / "&overview!C12} | C3: All | D3: Native Female | E3: Native Male | F3: Migrant Female | G3: Migrant Male | H3: Utility Native Male + Female | I3: Utility Migrant Male + Female | J3: Utility All Female | K3: Utility All Male | L3: Utility Other
B4: ⚠️ | C4: Do not change this sheet!
B5: Overview
A6: {=overview!A11} | C6: {=overview!C11}
A7: {=overview!A12} | C7: {=overview!C12}
A8: {=overview!$A49} | C8: {=overview!C49}
A9: {=overview!$A51} | C9: {=overview!C51}
A10: {=overview!$A60} | C10: {=overview!C60} | D10: {=overview!D60} | E10: {=overview!E60} | F10: {=overview!F60} | G10: {=overview!G60} | H10: {=overview!H60} | I10: {=overview!I60} | J10: {=overview!J60} | K10: {=overview!K60}
A11: {=overview!$A62} | C11: {=overview!C62}
B13: Population
A14: {=population!$A7} | C14: {=population!C7}
A15: {=population!$A9} | C15: {=population!C9} | D15: {=population!D9} | E15: {=population!E9} | F15: {=population!F9} | G15: {=population!G9} | H15: {=population!H9} | I15: {=population!I9} | J15: {=population!J9} | K15: {=population!K9}
A16: {=population!$A10} | C16: {=population!C10} | D16: {=population!D10} | E16: {=population!E10} | F16: {=population!F10} | G16: {=population!G10} | H16: {=population!H10} | I16: {=population!I10} | J16: {=population!J10} | K16: {=population!K10}
A17: {=population!$A11} | C17: {=population!C11} | D17: {=population!D11} | E17: {=population!E11} | F17: {=population!F11} | G17: {=population!G11} | H17: {=population!H11} | I17: {=population!I11} | J17: {=population!J11} | K17: {=population!K11}
A18: {=population!$A12} | C18: {=population!C12} | D18: {=population!D12} | E18: {=population!E12} | F18: {=population!F12} | G18: {=population!G12} | H18: {=population!H12} | I18: {=population!I12} | J18: {=population!J12} | K18: {=population!K12}
A19: {=population!$A13} | C19: {=population!C13} | D19: {=population!D13} | E19: {=population!E13} | F19: {=population!F13} | G19: {=population!G13} | H19: {=population!H13} | I19: {=population!I13} | J19: {=population!J13} | K19: {=population!K13}
A20: {=population!$A14} | C20: {=population!C14} | D20: {=population!D14} | E20: {=population!E14} | F20: {=population!F14} | G20: {=population!G14} | H20: {=population!H14} | I20: {=population!I14} | J20: {=population!J14} | K20: {=population!K14}
A21: {=population!$A15} | C21: {=population!C15} | D21: {=population!D15} | E21: {=population!E15} | F21: {=population!F15} | G21: {=population!G15} | H21: {=population!H15} | I21: {=population!I15} | J21: {=population!J15} | K21: {=population!K15}
A22: {=population!$A16} | C22: {=population!C16} | D22: {=population!D16} | E22: {=population!E16} | F22: {=population!F16} | G22: {=population!G16} | H22: {=population!H16} | I22: {=population!I16} | J22: {=population!J16} | K22: {=population!K16}
A23: {=population!$A17} | C23: {=population!C17} | D23: {=population!D17} | E23: {=population!E17} | F23: {=population!F17} | G23: {=population!G17} | H23: {=population!H17} | I23: {=population!I17} | J23: {=population!J17} | K23: {=population!K17}
A24: {=population!$A18} | C24: {=population!C18} | D24: {=population!D18} | E24: {=population!E18} | F24: {=population!F18} | G24: {=population!G18} | H24: {=population!H18} | I24: {=population!I18} | J24: {=population!J18} | K24: {=population!K18}
A25: {=population!$A19} | C25: {=population!C19} | D25: {=population!D19} | E25: {=population!E19} | F25: {=population!F19} | G25: {=population!G19} | H25: {=population!H19} | I25: {=population!I19} | J25: {=population!J19} | K25: {=population!K19}
A26: {=population!$A20} | C26: {=population!C20} | D26: {=population!D20} | E26: {=population!E20} | F26: {=population!F20} | G26: {=population!G20} | H26: {=population!H20} | I26: {=population!I20} | J26: {=population!J20} | K26: {=population!K20}
... A115: {=population!$A109} | C115: {=population!C109} | D115: {=population!D109} | E115: {=population!E109} | F115: {=population!F109} | G115: {=population!G109} | H115: {=population!H109} | I115: {=population!I109} | J115: {=population!J109} | K115: {=population!K109}
A116: {=population!$A111} | C116: {=population!C111}
B118: Births
A119: {=births!$A7} | H119: {=births!D7} | I119: {=births!F7}
A120: {=births!$A11} | C120: {=births!C11} | D120: {=births!D11} | E120: {=births!E11} | F120: {=births!F11} | G120: {=births!G11} | H120: {=births!H11} | I120: {=births!I11} | J120: {=births!J11} | K120: {=births!K11}
A121: {=births!$A13} | C121: {=births!C13}
A122: {=births!$A22} | C122: {=births!C22} | D122: {=births!D22} | E122: {=births!E22} | F122: {=births!F22} | G122: {=births!G22} | H122: {=births!H22} | I122: {=births!I22} | J122: {=births!J22} | K122: {=births!K22}
A123: {=births!$A23} | C123: {=births!C23} | D123: {=births!D23} | E123: {=births!E23} | F123: {=births!F23} | G123: {=births!G23} | H123: {=births!H23} | I123: {=births!I23} | J123: {=births!J23} | K123: {=births!K23}
A124: {=births!$A24} | C124: {=births!C24} | D124: {=births!D24} | E124: {=births!E24} | F124: {=births!F24} | G124: {=births!G24} | H124: {=births!H24} | I124: {=births!I24} | J124: {=births!J24} | K124: {=births!K24}
A125: {=births!$A25} | C125: {=births!C25} | D125: {=births!D25} | E125: {=births!E25} | F125: {=births!F25} | G125: {=births!G25} | H125: {=births!H25} | I125: {=births!I25} | J125: {=births!J25} | K125: {=births!K25}
A126: {=births!$A26} | C126: {=births!C26} | D126: {=births!D26} | E126: {=births!E26} | F126: {=births!F26} | G126: {=births!G26} | H126: {=births!H26} | I126: {=births!I26} | J126: {=births!J26} | K126: {=births!K26}
A127: {=births!$A27} | C127: {=births!C27} | D127: {=births!D27} | E127: {=births!E27} | F127: {=births!F27} | G127: {=births!G27} | H127: {=births!H27} | I127: {=births!I27} | J127: {=births!J27} | K127: {=births!K27}
A128: {=births!$A28} | C128: {=births!C28} | D128: {=births!D28} | E128: {=births!E28} | F128: {=births!F28} | G128: {=births!G28} | H128: {=births!H28} | I128: {=births!I28} | J128: {=births!J28} | K128: {=births!K28}
A129: {=births!$A29} | C129: {=births!C29} | D129: {=births!D29} | E129: {=births!E29} | F129: {=births!F29} | G129: {=births!G29} | H129: {=births!H29} | I129: {=births!I29} | J129: {=births!J29} | K129: {=births!K29}
A130: {=births!$A30} | C130: {=births!C30} | D130: {=births!D30} | E130: {=births!E30} | F130: {=births!F30} | G130: {=births!G30} | H130: {=births!H30} | I130: {=births!I30} | J130: {=births!J30} | K130: {=births!K30}
...
